Exceptions in Kotlin are used to handle and manage exceptional conditions or errors that may occur during the execution of a program. When an exceptional condition arises, such as a runtime error or an unexpected situation, an exception can be thrown to signal the occurrence of the problem. Exception handling allows you to gracefully handle these exceptional conditions and prevent your program from terminating abruptly.

Kotlin provides the following key elements for working with exceptions:

1.Throwing Exceptions:

To throw an exception explicitly, you can use the throw keyword followed by an instance of an exception class.

Example:

kotlin
Copy code
fun divide(a: Int, b: Int): Int {
    if (b == 0) {
        throw ArithmeticException("Cannot divide by zero")
    }
    return a / b
}
In the code above, the divide() function throws an ArithmeticException when attempting to divide by zero.




2.Catching Exceptions:

To handle exceptions, you can use a try-catch block. The try block contains the code that might throw an exception, and the catch block specifies the exception type to catch and provides the handling code.

Example:

kotlin
Copy code
fun main() {
    try {
        val result = divide(10, 0)
        println("Result: $result")
    } catch (e: ArithmeticException) {
        println("An exception occurred: ${e.message}")
    }
}
In the main() function, we invoke the divide() function that may throw an ArithmeticException. We use a try-catch block to catch the exception and handle it. In the catch block, we print an error message that contains the exception message.







3.Finally Block:

You can optionally include a finally block after the catch block. The code in the finally block is executed regardless of whether an exception was thrown or caught.

Example:

kotlin
Copy code
fun main() {
    try {
        val result = divide(10, 0)
        println("Result: $result")
    } catch (e: ArithmeticException) {
        println("An exception occurred: ${e.message}")
    } finally {
        println("Finally block executed")
    }
}
In the code above, the finally block is executed regardless of whether an exception occurred or not. It can be useful for performing cleanup operations or releasing resources.

Kotlin provides a range of built-in exception classes that cover common exceptional conditions, such as ArithmeticException, NullPointerException, IllegalArgumentException, etc. Additionally, you can define your own custom exception classes by inheriting from the Exception or RuntimeException class.

By using exception handling, you can make your program more robust and handle unexpected situations gracefully, ensuring that your program continues to execute without terminating abruptly when errors occur.
















MORE EXPLANANTION
******************************************************************************************************************************************


    
    In Kotlin, exceptions are unwanted or unexpected events that occur during the execution of a program. All exception classes are descendants of the Throwable class developersbreach.com. Unlike Java, Kotlin does not have checked exceptions; it only has unchecked exceptions, which are caught during runtime baeldung.com.

Some common exceptions in Kotlin include:

NullPointerException: Thrown when trying to invoke a property or method on a null object.
ArithmeticException: Thrown when performing invalid arithmetic operations on numbers, e.g., dividing by zero.
SecurityException: Thrown to indicate a security violation.
ArrayIndexOutOfBoundsException: Thrown when trying to access an invalid index value in an array geeksforgeeks.org.
In Kotlin, you can use throw to throw an exception object:

throw Exception("Throw me")
To handle exceptions, Kotlin provides try-catch blocks. You can enclose the code that might throw an exception within a try block, and then handle the exception in the corresponding catch block:

fun main() {
    try {
        val result = 10 / 0
        println(result)
    } catch (e: ArithmeticException) {
        println("Caught exception: $e")
    }
}
In this example, the try block contains code that may throw an ArithmeticException. If an exception is thrown, the catch block handles it by printing a message.

Kotlin also supports finally blocks, which contain code that will be executed regardless of whether an exception was thrown or not:

fun main() {
    try {
        val result = 10 / 0
        println(result)
    } catch (e: ArithmeticException) {
        println("Caught exception: $e")
    } finally {
        println("This will always be executed")
    }
}
In this example, the finally block is executed after the try or catch block, regardless of whether an exception occurred.


























































...
